<mujoco model="myXarm">
    <actuator>
        <!-- Physical limits of the actuator. -->
        <motor ctrllimited="true" ctrlrange="-80.0 80.0" joint="joint1" name="torq_j1"/>
        <motor ctrllimited="true" ctrlrange="-80.0 80.0" joint="joint2" name="torq_j2"/>
        <motor ctrllimited="true" ctrlrange="-80.0 80.0" joint="joint3" name="torq_j3"/>
        <motor ctrllimited="true" ctrlrange="-80.0 80.0" joint="joint4" name="torq_j4"/>
        <motor ctrllimited="true" ctrlrange="-80.0 80.0" joint="joint5" name="torq_j5"/>
        <motor ctrllimited="true" ctrlrange="-12.0 12.0" joint="joint6" name="torq_j6"/>
        <motor ctrllimited="true" ctrlrange="-12.0 12.0" joint="joint7" name="torq_j7"/>
    </actuator>
    <asset>
	    <!--<mesh name="link_base" file="assets/link_base.stl"/> -->   
	<mesh name="link0" file="assets/link_base.stl" />
        <mesh name="link1" file="assets/link1.stl" />
        <mesh name="link2" file="assets/link2.stl" />
        <mesh name="link3" file="assets/link3.stl" />
        <mesh name="link4" file="assets/link4.stl" />
        <mesh name="link5" file="assets/link5.stl" />
        <mesh name="link6" file="assets/link6.stl" />
        <mesh name="link7" file="assets/link7.stl" />
    </asset>
    <worldbody>
        <body name="base" pos="0 0 0">
            <!-- robot view -->
            <camera mode="fixed" name="robotview" pos="1.0 0 0.4" quat="0.653 0.271 0.271 0.653"/>
            <inertial diaginertia="0 0 0" mass="0" pos="0 0 0"/>
            <!-- mount attached here -->
            <body name="link0" pos="0 0 0">
                <inertial pos="0 0 0.05" mass="4" diaginertia="0.4 0.4 0.4" />
                <geom type="mesh" contype="0" conaffinity="0" group="1" mesh="link0" name="link0_visual" rgba="1 1 1 1" />
                <geom type="mesh" group="0" mesh="link0" name="link0_collision"/>
                <body name="link1" pos="0 0 0.333">
                    <inertial pos="0 0 -0.07" mass="3" diaginertia="0.3 0.3 0.3" />
                    <joint name="joint1" pos="0 0 0" axis="0 0 1" limited="true" range="-2.8973 2.8973" damping="0.1"/>
                    <geom type="mesh" contype="0" conaffinity="0" group="1" mesh="link1" name="link1_visual" rgba="1 1 1 1" />
                    <geom type="mesh" group="0" mesh="link1" name="link1_collision"/>
                    <body name="link2" pos="0 0 0" quat="0.707107 -0.707107 0 0">
                        <inertial pos="0 -0.1 0" mass="3" diaginertia="0.3 0.3 0.3" />
                        <joint name="joint2" pos="0 0 0" axis="0 0 1" limited="true" range="-1.7628 1.7628" damping="0.1"/>
                        <geom type="mesh" contype="0" conaffinity="0" group="1" mesh="link2" name="link2_visual" rgba="1 1 1 1" />
                        <geom type="mesh" group="0" mesh="link2" name="link2_collision"/>
                        <body name="link3" pos="0 -0.316 0" quat="0.707107 0.707107 0 0">
                            <inertial pos="0.04 0 -0.05" mass="2" diaginertia="0.2 0.2 0.2" />
                            <joint name="joint3" pos="0 0 0" axis="0 0 1" limited="true" range="-2.8973 2.8973" damping="0.1"/>
                            <geom type="mesh" contype="0" conaffinity="0" group="1" mesh="link3" name="link3_visual" rgba="1 1 1 1" />
                            <geom type="mesh" group="0" mesh="link3" name="link3_collision"/>
                            <body name="link4" pos="0.0825 0 0" quat="0.707107 0.707107 0 0">
                                <inertial pos="-0.04 0.05 0" mass="2" diaginertia="0.2 0.2 0.2" />
                                <joint name="joint4" pos="0 0 0" axis="0 0 1" limited="true" range="-3.0718 -0.0698" damping="0.1"/>
                                <geom type="mesh" contype="0" conaffinity="0" group="1" mesh="link4" name="link4_visual" rgba="1 1 1 1" />
                                <geom type="mesh" group="0" mesh="link4" name="link4_collision"/>
                                <body name="link5" pos="-0.0825 0.384 0" quat="0.707107 -0.707107 0 0">
                                    <inertial pos="0 0 -0.15" mass="2" diaginertia="0.2 0.2 0.2" />
                                    <joint name="joint5" pos="0 0 0" axis="0 0 1" limited="true" range="-2.8973 2.8973" damping="0.1"/>
                                    <geom type="mesh" contype="0" conaffinity="0" group="1" mesh="link5" name="link5_visual" rgba="1 1 1 1" />
                                    <geom type="mesh" group="0" mesh="link5" name="link5_collision"/>
                                    <body name="link6" pos="0 0 0" quat="0.707107 0.707107 0 0">
                                        <inertial pos="0.06 0 0" mass="1.5" diaginertia="0.1 0.1 0.1" />
                                        <joint name="joint6" pos="0 0 0" axis="0 0 1" limited="true" range="-0.0175 3.7525" damping="0.01"/>
                                        <geom type="mesh" contype="0" conaffinity="0" group="1" mesh="link6" name="link6_visual" rgba="1 1 1 1" />
                                        <geom type="mesh" group="0" mesh="link6" name="link6_collision"/>
                                        <body name="link7" pos="0.088 0 0" quat="0.707107 0.707107 0 0">
                                            <inertial pos="0 0 0.08" mass="0.5" diaginertia="0.05 0.05 0.05" />
                                            <joint name="joint7" pos="0 0 0" axis="0 0 1" limited="true" range="-2.8973 2.8973" damping="0.01"/>
                                            <geom type="mesh" contype="0" conaffinity="0" group="1" mesh="link7" name="link7_visual" rgba="1. 1. 1. 1." />
                                            <geom type="mesh" group="0" mesh="link7" name="link7_collision"/>
                                            <!-- rotate 135deg to align physically to the tool-->
                                            <body name="right_hand" pos="0 0 0.1065" quat="0.924 0 0 -0.383">
                                                <inertial pos="0 0 0" mass="0.5" diaginertia="0.05 0.05 0.05" />
                                                <!-- This camera points out from the eef. -->
                                                <camera mode="fixed" name="eye_in_hand" pos="0.05 0 0" quat="0 0.707108 0.707108 0" fovy="75"/>
                                                <!-- to add gripper -->
                                            </body>
                                        </body>
                                    </body>
                                </body>
                            </body>
                        </body>
                    </body>
                </body>
            </body>
        </body>
    </worldbody>
</mujoco>

